<?xml version="1.0"?>
<!--
  Robot: diff_drive_robot
  Generated by: LinkForge v1.0.0
  https://github.com/arounamounchili/linkforge
  Date: 2025-12-21
-->
<robot name="diff_drive_robot">
  <!-- Materials -->
  <material name="blue">
    <color rgba="0 0 1 1" />
  </material>
  <material name="black">
    <color rgba="0 0 0 1" />
  </material>
  <material name="white">
    <color rgba="1 1 1 1" />
  </material>
  <!-- Links -->
  <link name="base_link">
    <visual>
      <geometry>
        <box size="0.5 0.3 0.1" />
      </geometry>
      <material name="blue" />
    </visual>
    <collision>
      <geometry>
        <box size="0.5 0.3 0.1" />
      </geometry>
    </collision>
    <inertial>
      <mass value="5" />
      <inertia ixx="0.041667" ixy="0" ixz="0" iyy="0.108333" iyz="0" izz="0.141667" />
    </inertial>
  </link>
  <link name="left_wheel">
    <visual>
      <origin xyz="0 0 0.025" rpy="0 0 0" />
      <geometry>
        <cylinder radius="0.1" length="0.05" />
      </geometry>
      <material name="black" />
    </visual>
    <collision>
      <origin xyz="0 0 0.025" rpy="0 0 0" />
      <geometry>
        <cylinder radius="0.1" length="0.05" />
      </geometry>
    </collision>
    <inertial>
      <mass value="1" />
      <inertia ixx="0.002708" ixy="0" ixz="0" iyy="0.002708" iyz="0" izz="0.005" />
    </inertial>
  </link>
  <link name="right_wheel">
    <visual>
      <origin xyz="0 0 -0.025" rpy="0 0 0" />
      <geometry>
        <cylinder radius="0.1" length="0.05" />
      </geometry>
    </visual>
    <collision>
      <origin xyz="0 0 -0.025" rpy="0 0 0" />
      <geometry>
        <cylinder radius="0.1" length="0.05" />
      </geometry>
    </collision>
    <inertial>
      <mass value="1" />
      <inertia ixx="0.002708" ixy="0" ixz="0" iyy="0.002708" iyz="0" izz="0.005" />
    </inertial>
  </link>
  <link name="caster_wheel">
    <visual>
      <origin xyz="0 0 -0.05" rpy="0 0 0" />
      <geometry>
        <sphere radius="0.05" />
      </geometry>
      <material name="white" />
    </visual>
    <collision>
      <origin xyz="0 0 -0.05" rpy="0 0 0" />
      <geometry>
        <sphere radius="0.05" />
      </geometry>
    </collision>
    <inertial>
      <mass value="0.5" />
      <inertia ixx="0.0005" ixy="0" ixz="0" iyy="0.0005" iyz="0" izz="0.0005" />
    </inertial>
  </link>
  <!-- Joints -->
  <joint name="left_wheel_joint" type="continuous">
    <origin xyz="0 0.15 0" rpy="-1.570796 0 0" />
    <parent link="base_link" />
    <child link="left_wheel" />
    <axis xyz="0 1 0" />
  </joint>
  <joint name="right_wheel_joint" type="continuous">
    <origin xyz="0 -0.15 0" rpy="-1.570796 0 0" />
    <parent link="base_link" />
    <child link="right_wheel" />
    <axis xyz="0 1 0" />
  </joint>
  <joint name="caster_joint" type="fixed">
    <origin xyz="-0.2 0 -0.05" rpy="0 0 0" />
    <parent link="base_link" />
    <child link="caster_wheel" />
  </joint>
  <!-- Transmissions -->
  <transmission name="left_wheel_transmission">
    <type>transmission_interface/SimpleTransmission</type>
    <joint name="left_wheel_joint">
      <hardwareInterface>velocity</hardwareInterface>
    </joint>
    <actuator name="left_motor">
      <hardwareInterface>velocity</hardwareInterface>
      <mechanicalReduction>1</mechanicalReduction>
    </actuator>
  </transmission>
  <transmission name="right_wheel_transmission">
    <type>transmission_interface/SimpleTransmission</type>
    <joint name="right_wheel_joint">
      <hardwareInterface>velocity</hardwareInterface>
    </joint>
    <actuator name="right_motor">
      <hardwareInterface>velocity</hardwareInterface>
      <mechanicalReduction>1</mechanicalReduction>
    </actuator>
  </transmission>
  <!-- ROS2 Control -->
  <ros2_control name="GazeboSimSystem" type="system">
    <hardware>
      <plugin>gz_ros2_control/GazeboSimSystem</plugin>
    </hardware>
    <joint name="left_wheel_joint">
      <command_interface name="velocity" />
      <state_interface name="position" />
      <state_interface name="velocity" />
    </joint>
    <joint name="right_wheel_joint">
      <command_interface name="velocity" />
      <state_interface name="position" />
      <state_interface name="velocity" />
    </joint>
  </ros2_control>
  <gazebo>
    <plugin filename="libgz_ros2_control-system.so" name="gz_ros2_control::GazeboSimROS2ControlPlugin">
      <parameters>$(find robot_description)/config/controllers.yaml</parameters>
    </plugin>
  </gazebo>
</robot>
