<?xml version="1.0"?>
<!--
  Robot: dogbot
  Generated by: LinkForge v1.1.0
  https://github.com/arounamounchili/linkforge
  Date: 2026-01-24 07:49:31
-->
<robot name="dogbot">
  <!-- Materials -->
  <material name="body_color">
    <color rgba="0.8 0.8 0.8 1" />
  </material>
  <material name="accent_color">
    <color rgba="1 0.5 0 1" />
  </material>
  <material name="leg_color">
    <color rgba="0.3 0.3 0.3 1" />
  </material>
  <material name="foot_color">
    <color rgba="0.1 0.1 0.1 1" />
  </material>
  <!-- Links -->
  <link name="base_link">
    <visual>
      <geometry>
        <box size="0.5 0.25 0.12" />
      </geometry>
      <material name="body_color" />
    </visual>
    <visual>
      <origin xyz="0.25 0 0.08" rpy="0 0 0" />
      <geometry>
        <box size="0.1 0.15 0.1" />
      </geometry>
      <material name="accent_color" />
    </visual>
    <collision>
      <geometry>
        <box size="0.5 0.25 0.12" />
      </geometry>
    </collision>
    <inertial>
      <mass value="10" />
      <inertia ixx="0.064" ixy="0" ixz="0" iyy="0.22" iyz="0" izz="0.26" />
    </inertial>
  </link>
  <link name="front_left_hip">
    <visual>
      <origin xyz="0.05 0 0" rpy="1.5708 0 0" />
      <geometry>
        <cylinder radius="0.04" length="0.08" />
      </geometry>
      <material name="leg_color" />
    </visual>
    <collision>
      <origin xyz="0.05 0 0" rpy="1.5708 0 0" />
      <geometry>
        <cylinder radius="0.04" length="0.08" />
      </geometry>
    </collision>
    <inertial>
      <mass value="0.5" />
      <inertia ixx="0.0004" ixy="0" ixz="0" iyy="0.0004" iyz="0" izz="0.0004" />
    </inertial>
  </link>
  <link name="front_left_upper_leg">
    <visual>
      <origin xyz="0 0 -0.1" rpy="0 0 0" />
      <geometry>
        <box size="0.04 0.04 0.2" />
      </geometry>
      <material name="leg_color" />
    </visual>
    <collision>
      <origin xyz="0 0 -0.1" rpy="0 0 0" />
      <geometry>
        <box size="0.04 0.04 0.2" />
      </geometry>
    </collision>
    <inertial>
      <origin xyz="0 0 -0.1" rpy="0 0 0" />
      <mass value="1" />
      <inertia ixx="0.00346" ixy="0" ixz="0" iyy="0.00346" iyz="0" izz="0.00026" />
    </inertial>
  </link>
  <link name="front_left_lower_leg">
    <visual>
      <origin xyz="0 0 -0.1" rpy="0 0 0" />
      <geometry>
        <cylinder radius="0.02" length="0.2" />
      </geometry>
      <material name="leg_color" />
    </visual>
    <collision>
      <origin xyz="0 0 -0.1" rpy="0 0 0" />
      <geometry>
        <cylinder radius="0.02" length="0.2" />
      </geometry>
    </collision>
    <inertial>
      <origin xyz="0 0 -0.1" rpy="0 0 0" />
      <mass value="0.5" />
      <inertia ixx="0.0017" ixy="0" ixz="0" iyy="0.0017" iyz="0" izz="0.0001" />
    </inertial>
  </link>
  <link name="front_left_foot">
    <visual>
      <geometry>
        <sphere radius="0.03" />
      </geometry>
      <material name="foot_color" />
    </visual>
    <collision>
      <geometry>
        <sphere radius="0.03" />
      </geometry>
    </collision>
    <inertial>
      <mass value="0.1" />
      <inertia ixx="0.000036" ixy="0" ixz="0" iyy="0.000036" iyz="0" izz="0.000036" />
    </inertial>
  </link>
  <link name="front_right_hip">
    <visual>
      <origin xyz="0.05 0 0" rpy="1.5708 0 0" />
      <geometry>
        <cylinder radius="0.04" length="0.08" />
      </geometry>
      <material name="leg_color" />
    </visual>
    <collision>
      <origin xyz="0.05 0 0" rpy="1.5708 0 0" />
      <geometry>
        <cylinder radius="0.04" length="0.08" />
      </geometry>
    </collision>
    <inertial>
      <mass value="0.5" />
      <inertia ixx="0.0004" ixy="0" ixz="0" iyy="0.0004" iyz="0" izz="0.0004" />
    </inertial>
  </link>
  <link name="front_right_upper_leg">
    <visual>
      <origin xyz="0 0 -0.1" rpy="0 0 0" />
      <geometry>
        <box size="0.04 0.04 0.2" />
      </geometry>
      <material name="leg_color" />
    </visual>
    <collision>
      <origin xyz="0 0 -0.1" rpy="0 0 0" />
      <geometry>
        <box size="0.04 0.04 0.2" />
      </geometry>
    </collision>
    <inertial>
      <origin xyz="0 0 -0.1" rpy="0 0 0" />
      <mass value="1" />
      <inertia ixx="0.00346" ixy="0" ixz="0" iyy="0.00346" iyz="0" izz="0.00026" />
    </inertial>
  </link>
  <link name="front_right_lower_leg">
    <visual>
      <origin xyz="0 0 -0.1" rpy="0 0 0" />
      <geometry>
        <cylinder radius="0.02" length="0.2" />
      </geometry>
      <material name="leg_color" />
    </visual>
    <collision>
      <origin xyz="0 0 -0.1" rpy="0 0 0" />
      <geometry>
        <cylinder radius="0.02" length="0.2" />
      </geometry>
    </collision>
    <inertial>
      <origin xyz="0 0 -0.1" rpy="0 0 0" />
      <mass value="0.5" />
      <inertia ixx="0.0017" ixy="0" ixz="0" iyy="0.0017" iyz="0" izz="0.0001" />
    </inertial>
  </link>
  <link name="front_right_foot">
    <visual>
      <geometry>
        <sphere radius="0.03" />
      </geometry>
      <material name="foot_color" />
    </visual>
    <collision>
      <geometry>
        <sphere radius="0.03" />
      </geometry>
    </collision>
    <inertial>
      <mass value="0.1" />
      <inertia ixx="0.000036" ixy="0" ixz="0" iyy="0.000036" iyz="0" izz="0.000036" />
    </inertial>
  </link>
  <link name="rear_left_hip">
    <visual>
      <origin xyz="0.05 0 0" rpy="1.5708 0 0" />
      <geometry>
        <cylinder radius="0.04" length="0.08" />
      </geometry>
      <material name="leg_color" />
    </visual>
    <collision>
      <origin xyz="0.05 0 0" rpy="1.5708 0 0" />
      <geometry>
        <cylinder radius="0.04" length="0.08" />
      </geometry>
    </collision>
    <inertial>
      <mass value="0.5" />
      <inertia ixx="0.0004" ixy="0" ixz="0" iyy="0.0004" iyz="0" izz="0.0004" />
    </inertial>
  </link>
  <link name="rear_left_upper_leg">
    <visual>
      <origin xyz="0 0 -0.1" rpy="0 0 0" />
      <geometry>
        <box size="0.04 0.04 0.2" />
      </geometry>
      <material name="leg_color" />
    </visual>
    <collision>
      <origin xyz="0 0 -0.1" rpy="0 0 0" />
      <geometry>
        <box size="0.04 0.04 0.2" />
      </geometry>
    </collision>
    <inertial>
      <origin xyz="0 0 -0.1" rpy="0 0 0" />
      <mass value="1" />
      <inertia ixx="0.00346" ixy="0" ixz="0" iyy="0.00346" iyz="0" izz="0.00026" />
    </inertial>
  </link>
  <link name="rear_left_lower_leg">
    <visual>
      <origin xyz="0 0 -0.1" rpy="0 0 0" />
      <geometry>
        <cylinder radius="0.02" length="0.2" />
      </geometry>
      <material name="leg_color" />
    </visual>
    <collision>
      <origin xyz="0 0 -0.1" rpy="0 0 0" />
      <geometry>
        <cylinder radius="0.02" length="0.2" />
      </geometry>
    </collision>
    <inertial>
      <origin xyz="0 0 -0.1" rpy="0 0 0" />
      <mass value="0.5" />
      <inertia ixx="0.0017" ixy="0" ixz="0" iyy="0.0017" iyz="0" izz="0.0001" />
    </inertial>
  </link>
  <link name="rear_left_foot">
    <visual>
      <geometry>
        <sphere radius="0.03" />
      </geometry>
      <material name="foot_color" />
    </visual>
    <collision>
      <geometry>
        <sphere radius="0.03" />
      </geometry>
    </collision>
    <inertial>
      <mass value="0.1" />
      <inertia ixx="0.000036" ixy="0" ixz="0" iyy="0.000036" iyz="0" izz="0.000036" />
    </inertial>
  </link>
  <link name="rear_right_hip">
    <visual>
      <origin xyz="0.05 0 0" rpy="1.5708 0 0" />
      <geometry>
        <cylinder radius="0.04" length="0.08" />
      </geometry>
      <material name="leg_color" />
    </visual>
    <collision>
      <origin xyz="0.05 0 0" rpy="1.5708 0 0" />
      <geometry>
        <cylinder radius="0.04" length="0.08" />
      </geometry>
    </collision>
    <inertial>
      <mass value="0.5" />
      <inertia ixx="0.0004" ixy="0" ixz="0" iyy="0.0004" iyz="0" izz="0.0004" />
    </inertial>
  </link>
  <link name="rear_right_upper_leg">
    <visual>
      <origin xyz="0 0 -0.1" rpy="0 0 0" />
      <geometry>
        <box size="0.04 0.04 0.2" />
      </geometry>
      <material name="leg_color" />
    </visual>
    <collision>
      <origin xyz="0 0 -0.1" rpy="0 0 0" />
      <geometry>
        <box size="0.04 0.04 0.2" />
      </geometry>
    </collision>
    <inertial>
      <origin xyz="0 0 -0.1" rpy="0 0 0" />
      <mass value="1" />
      <inertia ixx="0.00346" ixy="0" ixz="0" iyy="0.00346" iyz="0" izz="0.00026" />
    </inertial>
  </link>
  <link name="rear_right_lower_leg">
    <visual>
      <origin xyz="0 0 -0.1" rpy="0 0 0" />
      <geometry>
        <cylinder radius="0.02" length="0.2" />
      </geometry>
      <material name="leg_color" />
    </visual>
    <collision>
      <origin xyz="0 0 -0.1" rpy="0 0 0" />
      <geometry>
        <cylinder radius="0.02" length="0.2" />
      </geometry>
    </collision>
    <inertial>
      <origin xyz="0 0 -0.1" rpy="0 0 0" />
      <mass value="0.5" />
      <inertia ixx="0.0017" ixy="0" ixz="0" iyy="0.0017" iyz="0" izz="0.0001" />
    </inertial>
  </link>
  <link name="rear_right_foot">
    <visual>
      <geometry>
        <sphere radius="0.03" />
      </geometry>
      <material name="foot_color" />
    </visual>
    <collision>
      <geometry>
        <sphere radius="0.03" />
      </geometry>
    </collision>
    <inertial>
      <mass value="0.1" />
      <inertia ixx="0.000036" ixy="0" ixz="0" iyy="0.000036" iyz="0" izz="0.000036" />
    </inertial>
  </link>
  <!-- Joints -->
  <joint name="front_left_hip_joint" type="revolute">
    <origin xyz="0.2 0.125 0" rpy="0 0 0" />
    <parent link="base_link" />
    <child link="front_left_hip" />
    <axis xyz="1 0 0" />
    <limit effort="20" velocity="10" lower="-0.785" upper="0.785" />
    <dynamics damping="0.5" friction="0.2" />
  </joint>
  <joint name="front_left_upper_leg_joint" type="revolute">
    <origin xyz="0.05 0.04 0" rpy="0 0 0" />
    <parent link="front_left_hip" />
    <child link="front_left_upper_leg" />
    <axis xyz="0 1 0" />
    <limit effort="20" velocity="10" lower="-1.57" upper="3.14" />
    <dynamics damping="0.5" friction="0.2" />
  </joint>
  <joint name="front_left_knee_joint" type="revolute">
    <origin xyz="0 0 -0.2" rpy="0 0 0" />
    <parent link="front_left_upper_leg" />
    <child link="front_left_lower_leg" />
    <axis xyz="0 1 0" />
    <limit effort="20" velocity="10" lower="-2.7" upper="-0.5" />
    <dynamics damping="0.5" friction="0.2" />
  </joint>
  <joint name="front_left_foot_fixed" type="fixed">
    <origin xyz="0 0 -0.2" rpy="0 0 0" />
    <parent link="front_left_lower_leg" />
    <child link="front_left_foot" />
  </joint>
  <joint name="front_right_hip_joint" type="revolute">
    <origin xyz="0.2 -0.125 0" rpy="0 0 0" />
    <parent link="base_link" />
    <child link="front_right_hip" />
    <axis xyz="1 0 0" />
    <limit effort="20" velocity="10" lower="-0.785" upper="0.785" />
    <dynamics damping="0.5" friction="0.2" />
  </joint>
  <joint name="front_right_upper_leg_joint" type="revolute">
    <origin xyz="0.05 -0.04 0" rpy="0 0 0" />
    <parent link="front_right_hip" />
    <child link="front_right_upper_leg" />
    <axis xyz="0 1 0" />
    <limit effort="20" velocity="10" lower="-1.57" upper="3.14" />
    <dynamics damping="0.5" friction="0.2" />
  </joint>
  <joint name="front_right_knee_joint" type="revolute">
    <origin xyz="0 0 -0.2" rpy="0 0 0" />
    <parent link="front_right_upper_leg" />
    <child link="front_right_lower_leg" />
    <axis xyz="0 1 0" />
    <limit effort="20" velocity="10" lower="-2.7" upper="-0.5" />
    <dynamics damping="0.5" friction="0.2" />
  </joint>
  <joint name="front_right_foot_fixed" type="fixed">
    <origin xyz="0 0 -0.2" rpy="0 0 0" />
    <parent link="front_right_lower_leg" />
    <child link="front_right_foot" />
  </joint>
  <joint name="rear_left_hip_joint" type="revolute">
    <origin xyz="-0.2 0.125 0" rpy="0 0 0" />
    <parent link="base_link" />
    <child link="rear_left_hip" />
    <axis xyz="1 0 0" />
    <limit effort="20" velocity="10" lower="-0.785" upper="0.785" />
    <dynamics damping="0.5" friction="0.2" />
  </joint>
  <joint name="rear_left_upper_leg_joint" type="revolute">
    <origin xyz="0.05 0.04 0" rpy="0 0 0" />
    <parent link="rear_left_hip" />
    <child link="rear_left_upper_leg" />
    <axis xyz="0 1 0" />
    <limit effort="20" velocity="10" lower="-1.57" upper="3.14" />
    <dynamics damping="0.5" friction="0.2" />
  </joint>
  <joint name="rear_left_knee_joint" type="revolute">
    <origin xyz="0 0 -0.2" rpy="0 0 0" />
    <parent link="rear_left_upper_leg" />
    <child link="rear_left_lower_leg" />
    <axis xyz="0 1 0" />
    <limit effort="20" velocity="10" lower="-2.7" upper="-0.5" />
    <dynamics damping="0.5" friction="0.2" />
  </joint>
  <joint name="rear_left_foot_fixed" type="fixed">
    <origin xyz="0 0 -0.2" rpy="0 0 0" />
    <parent link="rear_left_lower_leg" />
    <child link="rear_left_foot" />
  </joint>
  <joint name="rear_right_hip_joint" type="revolute">
    <origin xyz="-0.2 -0.125 0" rpy="0 0 0" />
    <parent link="base_link" />
    <child link="rear_right_hip" />
    <axis xyz="1 0 0" />
    <limit effort="20" velocity="10" lower="-0.785" upper="0.785" />
    <dynamics damping="0.5" friction="0.2" />
  </joint>
  <joint name="rear_right_upper_leg_joint" type="revolute">
    <origin xyz="0.05 -0.04 0" rpy="0 0 0" />
    <parent link="rear_right_hip" />
    <child link="rear_right_upper_leg" />
    <axis xyz="0 1 0" />
    <limit effort="20" velocity="10" lower="-1.57" upper="3.14" />
    <dynamics damping="0.5" friction="0.2" />
  </joint>
  <joint name="rear_right_knee_joint" type="revolute">
    <origin xyz="0 0 -0.2" rpy="0 0 0" />
    <parent link="rear_right_upper_leg" />
    <child link="rear_right_lower_leg" />
    <axis xyz="0 1 0" />
    <limit effort="20" velocity="10" lower="-2.7" upper="-0.5" />
    <dynamics damping="0.5" friction="0.2" />
  </joint>
  <joint name="rear_right_foot_fixed" type="fixed">
    <origin xyz="0 0 -0.2" rpy="0 0 0" />
    <parent link="rear_right_lower_leg" />
    <child link="rear_right_foot" />
  </joint>
  <!-- ROS2 Control -->
  <ros2_control name="GazeboSimSystem" type="system">
    <hardware>
      <plugin>gz_ros2_control/GazeboSimSystem</plugin>
    </hardware>
    <joint name="front_left_hip_joint">
      <command_interface name="effort" />
      <state_interface name="position" />
      <state_interface name="velocity" />
      <state_interface name="effort" />
    </joint>
    <joint name="front_left_upper_leg_joint">
      <command_interface name="effort" />
      <state_interface name="position" />
      <state_interface name="velocity" />
      <state_interface name="effort" />
    </joint>
    <joint name="front_left_knee_joint">
      <command_interface name="effort" />
      <state_interface name="position" />
      <state_interface name="velocity" />
      <state_interface name="effort" />
    </joint>
    <joint name="front_right_hip_joint">
      <command_interface name="effort" />
      <state_interface name="position" />
      <state_interface name="velocity" />
      <state_interface name="effort" />
    </joint>
    <joint name="front_right_upper_leg_joint">
      <command_interface name="effort" />
      <state_interface name="position" />
      <state_interface name="velocity" />
      <state_interface name="effort" />
    </joint>
    <joint name="front_right_knee_joint">
      <command_interface name="effort" />
      <state_interface name="position" />
      <state_interface name="velocity" />
      <state_interface name="effort" />
    </joint>
    <joint name="rear_left_hip_joint">
      <command_interface name="effort" />
      <state_interface name="position" />
      <state_interface name="velocity" />
      <state_interface name="effort" />
    </joint>
    <joint name="rear_left_upper_leg_joint">
      <command_interface name="effort" />
      <state_interface name="position" />
      <state_interface name="velocity" />
      <state_interface name="effort" />
    </joint>
    <joint name="rear_left_knee_joint">
      <command_interface name="effort" />
      <state_interface name="position" />
      <state_interface name="velocity" />
      <state_interface name="effort" />
    </joint>
    <joint name="rear_right_hip_joint">
      <command_interface name="effort" />
      <state_interface name="position" />
      <state_interface name="velocity" />
      <state_interface name="effort" />
    </joint>
    <joint name="rear_right_upper_leg_joint">
      <command_interface name="effort" />
      <state_interface name="position" />
      <state_interface name="velocity" />
      <state_interface name="effort" />
    </joint>
    <joint name="rear_right_knee_joint">
      <command_interface name="effort" />
      <state_interface name="position" />
      <state_interface name="velocity" />
      <state_interface name="effort" />
    </joint>
  </ros2_control>
  <!-- Gazebo -->
  <gazebo>
    <plugin name="gazebo_ros2_control" filename="libgz_ros2_control-system.so">
      <parameters>$(find robot_description)/config/controllers.yaml</parameters>
    </plugin>
  </gazebo>
</robot>
