<?xml version="1.0"?>
<!--
  Robot: diff_drive_robot
  Generated by: LinkForge v1.3.0
  https://github.com/arounamounchili/linkforge
  Date: 2026-04-04 12:37:00
-->
<robot name="diff_drive_robot">
  <!-- Links -->
  <link name="base_link">
    <visual>
      <geometry>
        <box size="0.4 0.3 0.1" />
      </geometry>
    </visual>
    <collision>
      <geometry>
        <box size="0.4 0.3 0.1" />
      </geometry>
    </collision>
    <inertial>
      <mass value="5" />
      <inertia ixx="0.041667" ixy="0" ixz="0" iyy="0.070833" iyz="0" izz="0.104167" />
    </inertial>
  </link>
  <link name="left_wheel">
    <visual>
      <geometry>
        <cylinder radius="0.1" length="0.05" />
      </geometry>
    </visual>
    <collision>
      <geometry>
        <cylinder radius="0.1" length="0.05" />
      </geometry>
    </collision>
    <inertial>
      <mass value="0.5" />
      <inertia ixx="0.001354" ixy="0" ixz="0" iyy="0.001354" iyz="0" izz="0.0025" />
    </inertial>
  </link>
  <link name="right_wheel">
    <visual>
      <geometry>
        <cylinder radius="0.1" length="0.05" />
      </geometry>
    </visual>
    <collision>
      <geometry>
        <cylinder radius="0.1" length="0.05" />
      </geometry>
    </collision>
    <inertial>
      <mass value="0.5" />
      <inertia ixx="0.001354" ixy="0" ixz="0" iyy="0.001354" iyz="0" izz="0.0025" />
    </inertial>
  </link>
  <link name="lidar_link">
    <visual>
      <geometry>
        <cylinder radius="0.03174" length="0.037866" />
      </geometry>
    </visual>
    <inertial>
      <mass value="1" />
      <inertia ixx="0.000371" ixy="0" ixz="0" iyy="0.000371" iyz="0" izz="0.000504" />
    </inertial>
  </link>
  <!-- Joints -->
  <joint name="left_wheel_joint" type="continuous">
    <origin xyz="0 0.175 0" rpy="1.570796 0 0" />
    <parent link="base_link" />
    <child link="left_wheel" />
    <axis xyz="0 1 0" />
    <limit effort="10" velocity="1" />
  </joint>
  <joint name="right_wheel_joint" type="continuous">
    <origin xyz="0 -0.175 0" rpy="1.570796 0 0" />
    <parent link="base_link" />
    <child link="right_wheel" />
    <axis xyz="0 1 0" />
    <limit effort="10" velocity="1" />
  </joint>
  <joint name="lidar_link_joint" type="fixed">
    <origin xyz="0 0 0.064282" rpy="0 0 0" />
    <parent link="base_link" />
    <child link="lidar_link" />
  </joint>
  <!-- ROS2 Control -->
  <ros2_control name="GazeboSimSystem" type="system">
    <hardware>
      <plugin>gz_ros2_control/GazeboSimSystem</plugin>
    </hardware>
    <joint name="right_wheel_joint">
      <command_interface name="velocity" />
      <state_interface name="position" />
      <state_interface name="velocity" />
    </joint>
    <joint name="left_wheel_joint">
      <command_interface name="velocity" />
      <state_interface name="position" />
      <state_interface name="velocity" />
    </joint>
  </ros2_control>
  <!-- Gazebo -->
  <gazebo>
    <plugin name="gazebo_ros2_control" filename="libgz_ros2_control-system.so">
      <parameters>$(find robot_description)/config/controllers.yaml</parameters>
    </plugin>
  </gazebo>
  <!-- Sensors -->
  <gazebo reference="lidar_link">
    <sensor name="lidar_link_sensor" type="gpu_lidar">
      <always_on>true</always_on>
      <update_rate>30</update_rate>
      <visualize>false</visualize>
      <topic>/lidar_link_sensor</topic>
      <ray>
        <scan>
          <horizontal>
            <samples>640</samples>
            <resolution>1</resolution>
            <min_angle>-1.570796</min_angle>
            <max_angle>1.570796</max_angle>
          </horizontal>
        </scan>
        <range>
          <min>0.1</min>
          <max>10</max>
          <resolution>0.01</resolution>
        </range>
      </ray>
    </sensor>
  </gazebo>
</robot>
