<?xml version="1.0"?>
<!--
  Robot: mobile_robot
  Generated by: LinkForge v1.3.0
  https://github.com/arounamounchili/linkforge
  Date: 2026-04-04 12:37:00
-->
<robot name="mobile_robot">
  <!-- Materials -->
  <material name="base_material">
    <color rgba="0.3 0.3 0.8 1" />
  </material>
  <material name="wheel_material">
    <color rgba="0.1 0.1 0.1 1" />
  </material>
  <material name="lidar_material">
    <color rgba="0.1 0.1 0.1 1" />
  </material>
  <!-- Links -->
  <link name="base_link">
    <visual>
      <geometry>
        <box size="0.4 0.3 0.12" />
      </geometry>
      <material name="base_material" />
    </visual>
    <collision>
      <geometry>
        <box size="0.4 0.3 0.12" />
      </geometry>
    </collision>
    <inertial>
      <mass value="8" />
      <inertia ixx="0.0696" ixy="0" ixz="0" iyy="0.1163" iyz="0" izz="0.1667" />
    </inertial>
  </link>
  <link name="front_left_wheel">
    <visual>
      <origin xyz="0 0 0" rpy="1.570796 0 0" />
      <geometry>
        <cylinder radius="0.08" length="0.05" />
      </geometry>
      <material name="wheel_material" />
    </visual>
    <collision>
      <origin xyz="0 0 0" rpy="1.570796 0 0" />
      <geometry>
        <cylinder radius="0.08" length="0.05" />
      </geometry>
    </collision>
    <inertial>
      <mass value="0.6" />
      <inertia ixx="0.001085" ixy="0" ixz="0" iyy="0.001085" iyz="0" izz="0.00192" />
    </inertial>
  </link>
  <link name="front_right_wheel">
    <visual>
      <origin xyz="0 0 0" rpy="1.570796 0 0" />
      <geometry>
        <cylinder radius="0.08" length="0.05" />
      </geometry>
      <material name="wheel_material" />
    </visual>
    <collision>
      <origin xyz="0 0 0" rpy="1.570796 0 0" />
      <geometry>
        <cylinder radius="0.08" length="0.05" />
      </geometry>
    </collision>
    <inertial>
      <mass value="0.6" />
      <inertia ixx="0.001085" ixy="0" ixz="0" iyy="0.001085" iyz="0" izz="0.00192" />
    </inertial>
  </link>
  <link name="rear_left_wheel">
    <visual>
      <origin xyz="0 0 0" rpy="1.570796 0 0" />
      <geometry>
        <cylinder radius="0.08" length="0.05" />
      </geometry>
      <material name="wheel_material" />
    </visual>
    <collision>
      <origin xyz="0 0 0" rpy="1.570796 0 0" />
      <geometry>
        <cylinder radius="0.08" length="0.05" />
      </geometry>
    </collision>
    <inertial>
      <mass value="0.6" />
      <inertia ixx="0.001085" ixy="0" ixz="0" iyy="0.001085" iyz="0" izz="0.00192" />
    </inertial>
  </link>
  <link name="rear_right_wheel">
    <visual>
      <origin xyz="0 0 0" rpy="1.570796 0 0" />
      <geometry>
        <cylinder radius="0.08" length="0.05" />
      </geometry>
      <material name="wheel_material" />
    </visual>
    <collision>
      <origin xyz="0 0 0" rpy="1.570796 0 0" />
      <geometry>
        <cylinder radius="0.08" length="0.05" />
      </geometry>
    </collision>
    <inertial>
      <mass value="0.6" />
      <inertia ixx="0.001085" ixy="0" ixz="0" iyy="0.001085" iyz="0" izz="0.00192" />
    </inertial>
  </link>
  <link name="lidar">
    <visual>
      <geometry>
        <cylinder radius="0.04" length="0.05" />
      </geometry>
      <material name="lidar_material" />
    </visual>
    <collision>
      <geometry>
        <cylinder radius="0.04" length="0.05" />
      </geometry>
    </collision>
    <inertial>
      <mass value="0.2" />
      <inertia ixx="0.000122" ixy="0" ixz="0" iyy="0.000122" iyz="0" izz="0.00016" />
    </inertial>
  </link>
  <!-- Joints -->
  <joint name="front_left_wheel_joint" type="continuous">
    <origin xyz="0.12 0.175 -0.02" rpy="0 0 0" />
    <parent link="base_link" />
    <child link="front_left_wheel" />
    <axis xyz="0 1 0" />
    <dynamics damping="0.1" friction="0.1" />
  </joint>
  <joint name="front_right_wheel_joint" type="continuous">
    <origin xyz="0.12 -0.175 -0.02" rpy="0 0 0" />
    <parent link="base_link" />
    <child link="front_right_wheel" />
    <axis xyz="0 1 0" />
    <dynamics damping="0.1" friction="0.1" />
  </joint>
  <joint name="rear_left_wheel_joint" type="continuous">
    <origin xyz="-0.12 0.175 -0.02" rpy="0 0 0" />
    <parent link="base_link" />
    <child link="rear_left_wheel" />
    <axis xyz="0 1 0" />
    <dynamics damping="0.1" friction="0.1" />
  </joint>
  <joint name="rear_right_wheel_joint" type="continuous">
    <origin xyz="-0.12 -0.175 -0.02" rpy="0 0 0" />
    <parent link="base_link" />
    <child link="rear_right_wheel" />
    <axis xyz="0 1 0" />
    <dynamics damping="0.1" friction="0.1" />
  </joint>
  <joint name="lidar_joint" type="fixed">
    <origin xyz="0 0 0.085" rpy="0 0 0" />
    <parent link="base_link" />
    <child link="lidar" />
  </joint>
  <!-- Sensors -->
  <gazebo reference="lidar">
    <sensor name="lidar_sensor" type="gpu_lidar">
      <always_on>true</always_on>
      <update_rate>30</update_rate>
      <visualize>false</visualize>
      <topic>scan</topic>
      <ray>
        <scan>
          <horizontal>
            <samples>640</samples>
            <resolution>1</resolution>
            <min_angle>-1.570796</min_angle>
            <max_angle>1.570796</max_angle>
          </horizontal>
        </scan>
        <range>
          <min>0.1</min>
          <max>10</max>
          <resolution>0.01</resolution>
        </range>
      </ray>
    </sensor>
  </gazebo>
</robot>
